<?xml version="1.0"?>
<robot name="allien_diff_bot">
  <link name="base_footprint"/>

  <joint name="base_joint" type="fixed">
    <parent link="base_footprint"/>
    <child link="base_link" />
    <origin xyz="0 0 0" rpy="0 0 0"/>
  </joint>
  <link name="base_link">
    <visual>
      <geometry>
        <cylinder length="0.08" radius="0.2"/>
      </geometry>
      <material name="silver">
        <color rgba="0.75 0.75 0.75 1"/>
      </material>
    </visual>
    <collision>
      <geometry>
        <cylinder length="0.08" radius="0.155"/>
      </geometry>
    </collision>
    <inertial>
      <mass value="1.0"/>
      <inertia ixx="0.015" iyy="0.0375" izz="0.0375" ixy="0" ixz="0" iyz="0"/>
    </inertial>
  </link>
  <link name="caster">
    <visual>
      <geometry>
        <cylinder length="0.08" radius="0.05"/>
      </geometry>
      <material name="silver"/>
    </visual>
    <collision>
      <geometry>
        <cylinder length="0.08" radius="0.05"/>
      </geometry>
    </collision>
    <inertial>
      <mass value="0.1"/>
      <inertia ixx="0.00083" iyy="0.00083" izz="0.000167" ixy="0" ixz="0" iyz="0"/>
    </inertial>
  </link>

  <joint name="caster_joint" type="continuous">
    <axis xyz="0 0 1"/>
    <parent link="base_link"/>
    <child link="caster"/>
    <origin rpy="0 0 0" xyz="0.15 0 0"/>
  </joint>

  <link name="front_wheel">
    <visual>
      <geometry>
        <cylinder length="0.05" radius="0.035"/>
      </geometry>
      <material name="black"/>
    </visual>
    <collision>
      <geometry>
        <cylinder length="0.05" radius="0.035"/>
      </geometry>
    </collision>
    <inertial>
      <mass value="0.1"/>
      <inertia ixx="5.1458e-5" iyy="5.1458e-5" izz="6.125e-5" ixy="0" ixz="0" iyz="0"/>
    </inertial>
  </link>

  <joint name="front_wheel_joint" type="continuous">
    <axis xyz="0 0 1"/>
    <parent link="caster"/>
    <child link="front_wheel"/>
    <origin rpy="-1.5708 0 0" xyz="0.05 0 -.05"/>
  </joint>
  <link name="back_caster">
    <visual>
      <geometry>
        <cylinder length="0.08" radius="0.05"/>
      </geometry>
      <material name="silver"/>
    </visual>
    <collision>
      <geometry>
        <cylinder length="0.08" radius="0.05"/>
      </geometry>
    </collision>
    <inertial>
      <mass value="0.1"/>
      <inertia ixx="0.00083" iyy="0.00083" izz="0.000167" ixy="0" ixz="0" iyz="0"/>
    </inertial>
  </link>

  <joint name="back_caster_joint" type="continuous">
    <axis xyz="0 0 1"/>
    <parent link="base_link"/>
    <child link="back_caster"/>
    <origin rpy="0 0 0" xyz="-0.15 0 0"/>
  </joint>

  <link name="back_wheel">
    <visual>
      <geometry>
        <cylinder length="0.05" radius="0.035"/>
      </geometry>
      <material name="black"/>
    </visual>
    <collision>
      <geometry>
        <cylinder length="0.05" radius="0.035"/>
      </geometry>
    </collision>
    <inertial>
      <mass value="0.1"/>
      <inertia ixx="5.1458e-5" iyy="5.1458e-5" izz="6.125e-5" ixy="0" ixz="0" iyz="0"/>
    </inertial>
  </link>

  <joint name="back_wheel_joint" type="continuous">
    <axis xyz="0 0 1"/>
    <parent link="back_caster"/>
    <child link="back_wheel"/>
    <origin rpy="-1.5708 0 0" xyz="0.05 0 -.05"/>
  </joint>
  <link name="right_wheel">
    <visual>
      <geometry>
        <cylinder length="0.05" radius="0.035"/>
      </geometry>
      <material name="black">
        <color rgba="0 0 0 1"/>
      </material>
    </visual>
    <collision>
      <geometry>
        <cylinder length="0.05" radius="0.035"/>
      </geometry>
    </collision>
    <inertial>
      <mass value="0.1"/>
      <inertia ixx="5.1458e-5" iyy="5.1458e-5" izz="6.125e-5" ixy="0" ixz="0" iyz="0"/>
    </inertial>
  </link>

  <joint name="right_wheel_joint" type="continuous">
    <axis xyz="0 0 1"/>
    <parent link="base_link"/>
    <child link="right_wheel"/>
    <origin rpy="-1.5708 0 0" xyz="0 -0.16 -.05"/>
  </joint>

  <link name="left_wheel">
    <visual>
      <geometry>
        <cylinder length="0.05" radius="0.035"/>
      </geometry>
      <material name="black"/>
    </visual>
    <collision>
      <geometry>
        <cylinder length="0.05" radius="0.035"/>
      </geometry>
    </collision>
    <inertial>
      <mass value="0.1"/>
      <inertia ixx="5.1458e-5" iyy="5.1458e-5" izz="6.125e-5" ixy="0" ixz="0" iyz="0"/>
    </inertial>
  </link>

  <joint name="left_wheel_joint" type="continuous">
    <axis xyz="0 0 1"/>
    <parent link="base_link"/>
    <child link="left_wheel"/>
    <origin rpy="-1.5708 0 0" xyz="0 0.16 -.05"/>
  </joint>
  <link name="middle_link">
    <visual>
      <geometry>
        <cylinder length="0.3" radius="0.15"/>
      </geometry>
      <material name="silver">
        <color rgba="0.75 0.75 0.75 1"/>
      </material>
    </visual>
    <collision>
      <geometry>
        <cylinder length="0.3" radius="0.15"/>
      </geometry>
    </collision>
    <inertial>
      <mass value="1.0"/>
      <inertia ixx="0.015" iyy="0.0375" izz="0.0375" ixy="0" ixz="0" iyz="0"/>
    </inertial>
  </link>
  <joint name="middle_joint" type="fixed">
    <axis xyz="0 0 1"/>
    <parent link="base_link"/>
    <child link="middle_link"/>
    <origin rpy="0 0 0" xyz="0 0 0.15"/>
  </joint>
  <link name="top_link">
    <visual>
      <geometry>
        <sphere radius="0.15"/>
      </geometry>
      <material name="silver"/>
    </visual>
    <collision>
      <geometry>
        <sphere radius="0.15"/>
      </geometry>
      <material name="silver"/>
    </collision> 
    <inertial>
      <mass value="0.1"/>
      <inertia ixx="0.00083" iyy="0.00083" izz="0.000167" ixy="0" ixz="0" iyz="0"/>
    </inertial>
  </link>

  <joint name="top_joint" type="fixed">
    <axis xyz="0 0 1"/>
    <parent link="middle_link"/>
    <child link="top_link"/>
    <origin rpy="0 0 0" xyz="0 0 0.15"/>
  </joint>
  <link name="neck_link">
    <visual>
      <geometry>
        <cylinder length="0.05" radius="0.05"/>
      </geometry>
      <material name="silver"/>
    </visual>
    <collision>
      <geometry>
        <cylinder length="0.05" radius="0.05"/>
      </geometry>
      <material name="silver"/>
    </collision>
    <inertial>
      <mass value="0.1"/>
      <inertia ixx="0.00083" iyy="0.00083" izz="0.000167" ixy="0" ixz="0" iyz="0"/>
    </inertial>
  </link>

  <joint name="neck_joint" type="fixed">
    <axis xyz="0 0 1"/>
    <parent link="top_link"/>
    <child link="neck_link"/>
    <origin rpy="0 0 0" xyz="0 0 0.175"/>
    <limit effort="30" velocity="1.0" lower="-0.7" upper="0.7" />
  </joint>
  <link name="face_link">
    <visual>
      <geometry>
        <box size="0.125 0.275 0.125"/>
      </geometry>
      <material name="silver"/>
    </visual>
    <collision>
      <geometry>
        <box size="0.125 0.275 0.125"/>
      </geometry>
      <material name="silver"/>
    </collision>
    <inertial>
      <mass value="0.1"/>
      <inertia ixx="0.00083" iyy="0.00083" izz="0.000167" ixy="0" ixz="0" iyz="0"/>
    </inertial>
  </link>

  <joint name="face_joint" type="fixed">
    <axis xyz="0 0 1"/>
    <parent link="neck_link"/>
    <child link="face_link"/>
    <origin rpy="0 0 0" xyz="0 0 0.08"/>
  </joint>
  <link name="eye_link">
    <visual>
      <geometry>
        <box size="0.03 0.23  0.06"/>
      </geometry>
      <material name="black"/>
    </visual>
    <collision>
      <geometry>
        <box size="0.03 0.23 0.06"/>

      </geometry>
    </collision>
    <inertial>
      <mass value="0.1"/>
      <inertia ixx="0.00083" iyy="0.00083" izz="0.000167" ixy="0" ixz="0" iyz="0"/>
    </inertial>
  </link>
  <joint name="eye_joint" type="fixed">
    <axis xyz="0 0 1"/>
    <parent link="face_link"/>
    <child link="eye_link"/>
    <origin rpy="0 0 0" xyz="0.07 0 0.02"/>
  </joint>
  <link name="antennae_link">
    <visual>
      <geometry>
        <cylinder length="0.05" radius="0.01"/>
      </geometry>
      <material name="black"/>
    </visual>
    <collision>
      <geometry>
        <cylinder length="0.05" radius="0.01"/>
      </geometry>
      <material name="black"/>
    </collision>
    <inertial>
      <mass value="0.1"/>
      <inertia ixx="0.00083" iyy="0.00083" izz="0.000167" ixy="0" ixz="0" iyz="0"/>
    </inertial>
  </link>
  <joint name="antennae_joint" type="fixed">
    <axis xyz="0 0 1"/>
    <parent link="face_link"/>
    <child link="antennae_link"/>
    <origin rpy="0 0 0" xyz="0 0 0.08"/>
  </joint>
  <link name="laser_link">
    <visual>
      <geometry>
        <sphere radius="0.02"/>
      </geometry>
      <material name="black"/>
    </visual>
    <collision>
      <geometry>
        <sphere radius="0.02"/>
      </geometry>
      <material name="black"/>
    </collision>
    <inertial>
      <mass value="0.1"/>
      <inertia ixx="0.00083" iyy="0.00083" izz="0.000167" ixy="0" ixz="0" iyz="0"/>
    </inertial> 
  </link>
  <joint name="laser_joint" type="fixed">
    <axis xyz="0 0 1"/>
    <parent link="antennae_link"/>
    <child link="laser_link"/>
    <origin rpy="0 0 0" xyz="0 0 0.025"/>
  </joint>
  <gazebo reference="base_link">
     <material>Gazebo/Silver</material>
  </gazebo>
  <gazebo reference="middle_link">
     <material>Gazebo/Silver</material>
  </gazebo>
  <gazebo reference="top_link">
     <material>Gazebo/Silver</material>
  </gazebo>
  <gazebo reference="neck_link">
     <material>Gazebo/Silver</material>
  </gazebo>
  <gazebo reference="face_link">
     <material>Gazebo/Silver</material>
  </gazebo>
  <gazebo reference="castor">
     <material>Gazebo/Silver</material>
  </gazebo>
  <gazebo reference="back_castor">
     <material>Gazebo/Silver</material>
  </gazebo>
  <gazebo reference="front_wheel">
     <material>Gazebo/Silver</material>
  </gazebo>
  <gazebo reference="back_wheel">
     <material>Gazebo/Silver</material>
  </gazebo>
  <gazebo reference="left_wheel">
     <material>Gazebo/Black</material>
  </gazebo>
  <gazebo reference="right_wheel">
     <material>Gazebo/Black</material>
  </gazebo>
  <gazebo reference="eye_link">
     <material>Gazebo/Black</material>
  </gazebo>
  <gazebo reference="antennae_link">
     <material>Gazebo/Black</material>
  </gazebo>
  <gazebo reference="sphere_link">
     <material>Gazebo/Black</material>
  </gazebo>
  <gazebo reference="laser_link">

    <sensor name="hls_lfcd_lds" type="ray">
            <always_on>false</always_on>
            <visualize>false</visualize>
            <pose>-0.032 0 0.171 0 0 0</pose>
            <update_rate>2</update_rate>
            <ray>
              <scan>
                <horizontal>
                  <samples>360</samples>
                  <resolution>1.000000</resolution>
                  <min_angle>0.000000</min_angle>
                  <max_angle>6.280000</max_angle>
                </horizontal>
              </scan>
              <range>
                <min>0.120000</min>
                <max>3.5</max>
                <resolution>0.015000</resolution>
              </range>
              <noise>
                <type>gaussian</type>
                <mean>0.0</mean>
                <stddev>0.01</stddev>
              </noise>
            </ray>
          

          <plugin name="scan" filename="libgazebo_ros_ray_sensor.so">
            <ros>
              <remapping>~/out:=scan</remapping>
              <!--<argument>ros-args -r ~/out:=scan</argument>-->
            </ros>
            <output_type>sensor_msgs/LaserScan</output_type>
            <frame_name>laser_link</frame_name>
          </plugin>
        </sensor>
    </gazebo>
      <gazebo>

    <plugin name="alliien_diff_drive" filename="libgazebo_ros_diff_drive.so">

      <ros>
        <!-- <namespace>/tb3</namespace> -->
      </ros>

      <update_rate>30</update_rate>

      <num_wheel_pairs>1</num_wheel_pairs>

      <!-- wheels -->
      <left_joint>left_wheel_joint</left_joint>
      <right_joint>right_wheel_joint</right_joint>

      <!-- kinematics -->
      <wheel_separation>0.32</wheel_separation>
      <wheel_diameter>0.07</wheel_diameter>

      <!-- limits -->
      <max_wheel_torque>30</max_wheel_torque>
      <max_wheel_acceleration>1.0</max_wheel_acceleration>

      <command_topic>cmd_vel</command_topic>

      <!-- output -->
      <publish_odom>true</publish_odom>
      <publish_odom_tf>true</publish_odom_tf>
      <publish_wheel_tf>false</publish_wheel_tf>

      <odometry_topic>odom</odometry_topic>
      <odometry_frame>odom</odometry_frame>
      <robot_base_frame>base_footprint</robot_base_frame>

    </plugin>

    <plugin name="rover_joint_state" filename="libgazebo_ros_joint_state_publisher.so">
      <ros>
        <!-- <namespace>/tb3</namespace> -->
        <remapping>~/out:=joint_states</remapping>
      </ros>
      <update_rate>30</update_rate>
      <joint_name>left_wheel_joint</joint_name>
      <joint_name>right_wheel_joint</joint_name>
      <joint_name>caster_joint</joint_name>
      <joint_name>back_wheel_joint</joint_name>
      <joint_name>back_caster_joint</joint_name>
      <joint_name>front_wheel_joint</joint_name>
    </plugin>

  </gazebo>
  
    <joint name="imu_joint" type="fixed">
    <parent link="base_link"/>
    <child link="imu_link"/>
    <origin xyz="0.0 0 0.068" rpy="0 0 0"/>
  </joint>

  <link name="imu_link"/>


  
</robot>
